2024-04-05 12:51:34,430 INFO    StreamThr :13140 [internal.py:wandb_internal():86] W&B internal server running at pid: 13140, started at: 2024-04-05 12:51:34.428832
2024-04-05 12:51:34,431 DEBUG   HandlerThread:13140 [handler.py:handle_request():146] handle_request: status
2024-04-05 12:51:34,437 INFO    WriterThread:13140 [datastore.py:open_for_write():87] open: C:\Users\Matrix\Documents\Code\FedMut\FedMut\wandb\run-20240405_125134-anaplzca\run-anaplzca.wandb
2024-04-05 12:51:34,437 DEBUG   SenderThread:13140 [sender.py:send():379] send: header
2024-04-05 12:51:34,438 DEBUG   SenderThread:13140 [sender.py:send():379] send: run
2024-04-05 12:51:35,503 ERROR   SenderThread:13140 [internal_api.py:execute():373] 400 response executing GraphQL.
2024-04-05 12:51:35,504 ERROR   SenderThread:13140 [internal_api.py:execute():374] {"errors":[{"message":"you may not log runs directly to your organization, please try using your team entity","path":["upsertBucket"]}],"data":{"upsertBucket":null}}
2024-04-05 12:51:35,506 ERROR   SenderThread:13140 [sender.py:send_run():971] you may not log runs directly to your organization, please try using your team entity (Error 400: Bad Request)
Traceback (most recent call last):
  File "C:\Users\Matrix\.conda\envs\flower\lib\site-packages\wandb\apis\normalize.py", line 41, in wrapper
    return func(*args, **kwargs)
  File "C:\Users\Matrix\.conda\envs\flower\lib\site-packages\wandb\sdk\internal\internal_api.py", line 2217, in upsert_run
    response = self.gql(
  File "C:\Users\Matrix\.conda\envs\flower\lib\site-packages\wandb\sdk\internal\internal_api.py", line 341, in gql
    ret = self._retry_gql(
  File "C:\Users\Matrix\.conda\envs\flower\lib\site-packages\wandb\sdk\lib\retry.py", line 131, in __call__
    result = self._call_fn(*args, **kwargs)
  File "C:\Users\Matrix\.conda\envs\flower\lib\site-packages\wandb\sdk\internal\internal_api.py", line 369, in execute
    return self.client.execute(*args, **kwargs)  # type: ignore
  File "C:\Users\Matrix\.conda\envs\flower\lib\site-packages\wandb\vendor\gql-0.2.0\wandb_gql\client.py", line 52, in execute
    result = self._get_result(document, *args, **kwargs)
  File "C:\Users\Matrix\.conda\envs\flower\lib\site-packages\wandb\vendor\gql-0.2.0\wandb_gql\client.py", line 60, in _get_result
    return self.transport.execute(document, *args, **kwargs)
  File "C:\Users\Matrix\.conda\envs\flower\lib\site-packages\wandb\sdk\lib\gql_request.py", line 59, in execute
    request.raise_for_status()
  File "C:\Users\Matrix\AppData\Roaming\Python\Python310\site-packages\requests\models.py", line 1021, in raise_for_status
    raise HTTPError(http_error_msg, response=self)
requests.exceptions.HTTPError: 400 Client Error: Bad Request for url: https://api.wandb.ai/graphql

During handling of the above exception, another exception occurred:

Traceback (most recent call last):
  File "C:\Users\Matrix\.conda\envs\flower\lib\site-packages\wandb\sdk\internal\sender.py", line 969, in send_run
    server_run = self._init_run(run, config_value_dict)
  File "C:\Users\Matrix\.conda\envs\flower\lib\site-packages\wandb\sdk\internal\sender.py", line 1014, in _init_run
    server_run, inserted, server_messages = self._api.upsert_run(
  File "C:\Users\Matrix\.conda\envs\flower\lib\site-packages\wandb\apis\normalize.py", line 51, in wrapper
    raise CommError(message, error)
wandb.errors.CommError: you may not log runs directly to your organization, please try using your team entity (Error 400: Bad Request)
2024-04-05 12:51:36,156 DEBUG   HandlerThread:13140 [handler.py:handle_request():146] handle_request: shutdown
2024-04-05 12:51:36,156 INFO    HandlerThread:13140 [handler.py:finish():866] shutting down handler
2024-04-05 12:51:36,463 INFO    WriterThread:13140 [datastore.py:close():296] close: C:\Users\Matrix\Documents\Code\FedMut\FedMut\wandb\run-20240405_125134-anaplzca\run-anaplzca.wandb
2024-04-05 12:51:36,508 INFO    SenderThread:13140 [sender.py:finish():1546] shutting down sender
