2024-04-13 02:10:04,939 INFO    StreamThr :10219 [internal.py:wandb_internal():86] W&B internal server running at pid: 10219, started at: 2024-04-13 02:10:04.938755
2024-04-13 02:10:04,946 DEBUG   HandlerThread:10219 [handler.py:handle_request():144] handle_request: status
2024-04-13 02:10:04,948 INFO    WriterThread:10219 [datastore.py:open_for_write():85] open: /home/ubuntu/wjh/FedMut/FedMut/wandb/run-20240413_021004-4b41d82u/run-4b41d82u.wandb
2024-04-13 02:10:04,949 DEBUG   SenderThread:10219 [sender.py:send():379] send: header
2024-04-13 02:10:04,949 DEBUG   SenderThread:10219 [sender.py:send():379] send: run
2024-04-13 02:10:09,947 DEBUG   HandlerThread:10219 [handler.py:handle_request():144] handle_request: keepalive
2024-04-13 02:10:14,949 DEBUG   HandlerThread:10219 [handler.py:handle_request():144] handle_request: keepalive
2024-04-13 02:10:19,950 DEBUG   HandlerThread:10219 [handler.py:handle_request():144] handle_request: keepalive
2024-04-13 02:10:24,952 DEBUG   HandlerThread:10219 [handler.py:handle_request():144] handle_request: keepalive
2024-04-13 02:10:29,954 DEBUG   HandlerThread:10219 [handler.py:handle_request():144] handle_request: keepalive
2024-04-13 02:10:34,954 DEBUG   HandlerThread:10219 [handler.py:handle_request():144] handle_request: keepalive
2024-04-13 02:10:39,956 DEBUG   HandlerThread:10219 [handler.py:handle_request():144] handle_request: keepalive
2024-04-13 02:10:40,005 INFO    SenderThread:10219 [retry.py:__call__():172] Retry attempt failed:
Traceback (most recent call last):
  File "/home/ubuntu/anaconda3/envs/lrx/lib/python3.9/site-packages/urllib3/connection.py", line 174, in _new_conn
    conn = connection.create_connection(
  File "/home/ubuntu/anaconda3/envs/lrx/lib/python3.9/site-packages/urllib3/util/connection.py", line 95, in create_connection
    raise err
  File "/home/ubuntu/anaconda3/envs/lrx/lib/python3.9/site-packages/urllib3/util/connection.py", line 85, in create_connection
    sock.connect(sa)
socket.timeout: timed out

During handling of the above exception, another exception occurred:

Traceback (most recent call last):
  File "/home/ubuntu/anaconda3/envs/lrx/lib/python3.9/site-packages/urllib3/connectionpool.py", line 714, in urlopen
    httplib_response = self._make_request(
  File "/home/ubuntu/anaconda3/envs/lrx/lib/python3.9/site-packages/urllib3/connectionpool.py", line 403, in _make_request
    self._validate_conn(conn)
  File "/home/ubuntu/anaconda3/envs/lrx/lib/python3.9/site-packages/urllib3/connectionpool.py", line 1053, in _validate_conn
    conn.connect()
  File "/home/ubuntu/anaconda3/envs/lrx/lib/python3.9/site-packages/urllib3/connection.py", line 363, in connect
    self.sock = conn = self._new_conn()
  File "/home/ubuntu/anaconda3/envs/lrx/lib/python3.9/site-packages/urllib3/connection.py", line 179, in _new_conn
    raise ConnectTimeoutError(
urllib3.exceptions.ConnectTimeoutError: (<urllib3.connection.HTTPSConnection object at 0x7f5ac46a0760>, 'Connection to api.wandb.ai timed out. (connect timeout=10)')

During handling of the above exception, another exception occurred:

Traceback (most recent call last):
  File "/home/ubuntu/anaconda3/envs/lrx/lib/python3.9/site-packages/requests/adapters.py", line 486, in send
    resp = conn.urlopen(
  File "/home/ubuntu/anaconda3/envs/lrx/lib/python3.9/site-packages/urllib3/connectionpool.py", line 798, in urlopen
    retries = retries.increment(
  File "/home/ubuntu/anaconda3/envs/lrx/lib/python3.9/site-packages/urllib3/util/retry.py", line 592, in increment
    raise MaxRetryError(_pool, url, error or ResponseError(cause))
urllib3.exceptions.MaxRetryError: HTTPSConnectionPool(host='api.wandb.ai', port=443): Max retries exceeded with url: /graphql (Caused by ConnectTimeoutError(<urllib3.connection.HTTPSConnection object at 0x7f5ac46a0760>, 'Connection to api.wandb.ai timed out. (connect timeout=10)'))

During handling of the above exception, another exception occurred:

Traceback (most recent call last):
  File "/home/ubuntu/anaconda3/envs/lrx/lib/python3.9/site-packages/wandb/sdk/lib/retry.py", line 131, in __call__
    result = self._call_fn(*args, **kwargs)
  File "/home/ubuntu/anaconda3/envs/lrx/lib/python3.9/site-packages/wandb/sdk/internal/internal_api.py", line 323, in execute
    return self.client.execute(*args, **kwargs)  # type: ignore
  File "/home/ubuntu/anaconda3/envs/lrx/lib/python3.9/site-packages/wandb/vendor/gql-0.2.0/wandb_gql/client.py", line 52, in execute
    result = self._get_result(document, *args, **kwargs)
  File "/home/ubuntu/anaconda3/envs/lrx/lib/python3.9/site-packages/wandb/vendor/gql-0.2.0/wandb_gql/client.py", line 60, in _get_result
    return self.transport.execute(document, *args, **kwargs)
  File "/home/ubuntu/anaconda3/envs/lrx/lib/python3.9/site-packages/wandb/sdk/lib/gql_request.py", line 55, in execute
    request = self.session.post(self.url, **post_args)
  File "/home/ubuntu/anaconda3/envs/lrx/lib/python3.9/site-packages/requests/sessions.py", line 637, in post
    return self.request("POST", url, data=data, json=json, **kwargs)
  File "/home/ubuntu/anaconda3/envs/lrx/lib/python3.9/site-packages/requests/sessions.py", line 589, in request
    resp = self.send(prep, **send_kwargs)
  File "/home/ubuntu/anaconda3/envs/lrx/lib/python3.9/site-packages/requests/sessions.py", line 703, in send
    r = adapter.send(request, **kwargs)
  File "/home/ubuntu/anaconda3/envs/lrx/lib/python3.9/site-packages/requests/adapters.py", line 507, in send
    raise ConnectTimeout(e, request=request)
requests.exceptions.ConnectTimeout: HTTPSConnectionPool(host='api.wandb.ai', port=443): Max retries exceeded with url: /graphql (Caused by ConnectTimeoutError(<urllib3.connection.HTTPSConnection object at 0x7f5ac46a0760>, 'Connection to api.wandb.ai timed out. (connect timeout=10)'))
2024-04-13 02:10:44,957 DEBUG   HandlerThread:10219 [handler.py:handle_request():144] handle_request: keepalive
2024-04-13 02:10:49,958 DEBUG   HandlerThread:10219 [handler.py:handle_request():144] handle_request: keepalive
2024-04-13 02:10:54,960 DEBUG   HandlerThread:10219 [handler.py:handle_request():144] handle_request: keepalive
2024-04-13 02:10:59,962 DEBUG   HandlerThread:10219 [handler.py:handle_request():144] handle_request: keepalive
2024-04-13 02:11:04,963 DEBUG   HandlerThread:10219 [handler.py:handle_request():144] handle_request: cancel
2024-04-13 02:11:04,964 DEBUG   HandlerThread:10219 [handler.py:handle_request():144] handle_request: cancel
2024-04-13 02:11:06,977 DEBUG   HandlerThread:10219 [handler.py:handle_request():144] handle_request: shutdown
2024-04-13 02:11:06,978 INFO    HandlerThread:10219 [handler.py:finish():857] shutting down handler
2024-04-13 02:11:07,965 INFO    WriterThread:10219 [datastore.py:close():294] close: /home/ubuntu/wjh/FedMut/FedMut/wandb/run-20240413_021004-4b41d82u/run-4b41d82u.wandb
2024-04-13 02:11:14,387 DEBUG   SenderThread:10219 [sender.py:send():388] Record cancelled: run
2024-04-13 02:11:14,388 INFO    SenderThread:10219 [sender.py:finish():1552] shutting down sender
