2024-04-13 02:05:59,679 INFO    MainThread:9709 [wandb_setup.py:_flush():76] Current SDK version is 0.15.8
2024-04-13 02:05:59,679 INFO    MainThread:9709 [wandb_setup.py:_flush():76] Configure stats pid to 9709
2024-04-13 02:05:59,679 INFO    MainThread:9709 [wandb_setup.py:_flush():76] Loading settings from /home/ubuntu/.config/wandb/settings
2024-04-13 02:05:59,679 INFO    MainThread:9709 [wandb_setup.py:_flush():76] Loading settings from /home/ubuntu/wjh/FedMut/FedMut/wandb/settings
2024-04-13 02:05:59,679 INFO    MainThread:9709 [wandb_setup.py:_flush():76] Loading settings from environment variables: {}
2024-04-13 02:05:59,679 INFO    MainThread:9709 [wandb_setup.py:_flush():76] Applying setup settings: {'_disable_service': False}
2024-04-13 02:05:59,679 INFO    MainThread:9709 [wandb_setup.py:_flush():76] Inferring run settings from compute environment: {'program_relpath': 'main_fed.py', 'program': '/home/ubuntu/wjh/FedMut/FedMut/main_fed.py'}
2024-04-13 02:05:59,679 INFO    MainThread:9709 [wandb_init.py:_log_setup():507] Logging user logs to /home/ubuntu/wjh/FedMut/FedMut/wandb/run-20240413_020559-0batp16o/logs/debug.log
2024-04-13 02:05:59,679 INFO    MainThread:9709 [wandb_init.py:_log_setup():508] Logging internal logs to /home/ubuntu/wjh/FedMut/FedMut/wandb/run-20240413_020559-0batp16o/logs/debug-internal.log
2024-04-13 02:05:59,680 INFO    MainThread:9709 [wandb_init.py:init():547] calling init triggers
2024-04-13 02:05:59,680 INFO    MainThread:9709 [wandb_init.py:init():554] wandb.init called with sweep_config: {}
config: {'epochs': 750, 'num_users': 100, 'frac': 0.1, 'local_ep': 5, 'local_bs': 50, 'bs': 128, 'optimizer': 'sgd', 'lr': 0.05, 'momentum': 0.5, 'split': 'user', 'algorithm': 'FedAvg', 'limit_time': 300000, 'model': 'vgg', 'kernel_num': 9, 'kernel_sizes': '3,4,5', 'norm': 'batch_norm', 'num_filters': 32, 'max_pool': 'True', 'use_project_head': 0, 'out_dim': 256, 'dataset': 'cifar10', 'generate_data': 0, 'iid': 1, 'noniid_case': 0, 'data_beta': 0.5, 'num_classes': 10, 'num_channels': 3, 'gpu': 0, 'stopping_rounds': 10, 'verbose': False, 'seed': 1, 'prox_alpha': 0.01, 'ensemble_alpha': 0.2, 'temperature': 0.5, 'model_buffer_size': 1, 'pool_option': 'FIFO', 'sim_type': 'L1', 'p': 2.0, 'trans_beta': 500, 'radius': 4.0, 'min_radius': 0.1, 'mut_acc_rate': 0.3, 'mut_bound': 50, 'sparse': True, 'fix': True, 'sparse_init': 'ERK', 'growth': 'random', 'death': 'magnitude', 'redistribution': 'none', 'death_rate': 0.5, 'density': 1.0, 'density_local': 0.8, 'update_frequency': 100, 'decay_schedule': 'cosine', 'multiplier': 1, 'exname': '独非独立Avg200+半稀疏0.8  --epoch 750\npython main_fed.py --sparse  --sparse_init ERK --fix --dataset cifar10  --model vgg --algorithm FedAvg --density 1 --density_local 0.8 --lr 0.05  --exname 独非独立Avg200+半稀疏0.8', 'finetuning': False, 'helf_sparse': False, 'device': device(type='cuda', index=0)}
2024-04-13 02:05:59,680 INFO    MainThread:9709 [wandb_init.py:init():596] starting backend
2024-04-13 02:05:59,680 INFO    MainThread:9709 [wandb_init.py:init():600] setting up manager
2024-04-13 02:05:59,681 INFO    MainThread:9709 [backend.py:_multiprocessing_setup():106] multiprocessing start_methods=fork,spawn,forkserver, using: spawn
2024-04-13 02:05:59,684 INFO    MainThread:9709 [wandb_init.py:init():606] backend started and connected
2024-04-13 02:05:59,693 INFO    MainThread:9709 [wandb_init.py:init():697] updated telemetry
2024-04-13 02:05:59,694 INFO    MainThread:9709 [wandb_init.py:init():730] communicating run to backend with 60.0 second timeout
2024-04-13 02:06:28,430 INFO    Thread-1  :9709 [retry.py:__call__():172] Retry attempt failed:
Traceback (most recent call last):
  File "/home/ubuntu/anaconda3/envs/lrx/lib/python3.9/site-packages/urllib3/connection.py", line 174, in _new_conn
    conn = connection.create_connection(
  File "/home/ubuntu/anaconda3/envs/lrx/lib/python3.9/site-packages/urllib3/util/connection.py", line 95, in create_connection
    raise err
  File "/home/ubuntu/anaconda3/envs/lrx/lib/python3.9/site-packages/urllib3/util/connection.py", line 85, in create_connection
    sock.connect(sa)
socket.timeout: timed out

During handling of the above exception, another exception occurred:

Traceback (most recent call last):
  File "/home/ubuntu/anaconda3/envs/lrx/lib/python3.9/site-packages/urllib3/connectionpool.py", line 714, in urlopen
    httplib_response = self._make_request(
  File "/home/ubuntu/anaconda3/envs/lrx/lib/python3.9/site-packages/urllib3/connectionpool.py", line 403, in _make_request
    self._validate_conn(conn)
  File "/home/ubuntu/anaconda3/envs/lrx/lib/python3.9/site-packages/urllib3/connectionpool.py", line 1053, in _validate_conn
    conn.connect()
  File "/home/ubuntu/anaconda3/envs/lrx/lib/python3.9/site-packages/urllib3/connection.py", line 363, in connect
    self.sock = conn = self._new_conn()
  File "/home/ubuntu/anaconda3/envs/lrx/lib/python3.9/site-packages/urllib3/connection.py", line 179, in _new_conn
    raise ConnectTimeoutError(
urllib3.exceptions.ConnectTimeoutError: (<urllib3.connection.HTTPSConnection object at 0x7f1ab86e4a00>, 'Connection to api.wandb.ai timed out. (connect timeout=10)')

During handling of the above exception, another exception occurred:

Traceback (most recent call last):
  File "/home/ubuntu/anaconda3/envs/lrx/lib/python3.9/site-packages/requests/adapters.py", line 486, in send
    resp = conn.urlopen(
  File "/home/ubuntu/anaconda3/envs/lrx/lib/python3.9/site-packages/urllib3/connectionpool.py", line 798, in urlopen
    retries = retries.increment(
  File "/home/ubuntu/anaconda3/envs/lrx/lib/python3.9/site-packages/urllib3/util/retry.py", line 592, in increment
    raise MaxRetryError(_pool, url, error or ResponseError(cause))
urllib3.exceptions.MaxRetryError: HTTPSConnectionPool(host='api.wandb.ai', port=443): Max retries exceeded with url: /graphql (Caused by ConnectTimeoutError(<urllib3.connection.HTTPSConnection object at 0x7f1ab86e4a00>, 'Connection to api.wandb.ai timed out. (connect timeout=10)'))

During handling of the above exception, another exception occurred:

Traceback (most recent call last):
  File "/home/ubuntu/anaconda3/envs/lrx/lib/python3.9/site-packages/wandb/sdk/lib/retry.py", line 131, in __call__
    result = self._call_fn(*args, **kwargs)
  File "/home/ubuntu/anaconda3/envs/lrx/lib/python3.9/site-packages/wandb/sdk/internal/internal_api.py", line 323, in execute
    return self.client.execute(*args, **kwargs)  # type: ignore
  File "/home/ubuntu/anaconda3/envs/lrx/lib/python3.9/site-packages/wandb/vendor/gql-0.2.0/wandb_gql/client.py", line 52, in execute
    result = self._get_result(document, *args, **kwargs)
  File "/home/ubuntu/anaconda3/envs/lrx/lib/python3.9/site-packages/wandb/vendor/gql-0.2.0/wandb_gql/client.py", line 60, in _get_result
    return self.transport.execute(document, *args, **kwargs)
  File "/home/ubuntu/anaconda3/envs/lrx/lib/python3.9/site-packages/wandb/sdk/lib/gql_request.py", line 55, in execute
    request = self.session.post(self.url, **post_args)
  File "/home/ubuntu/anaconda3/envs/lrx/lib/python3.9/site-packages/requests/sessions.py", line 637, in post
    return self.request("POST", url, data=data, json=json, **kwargs)
  File "/home/ubuntu/anaconda3/envs/lrx/lib/python3.9/site-packages/requests/sessions.py", line 589, in request
    resp = self.send(prep, **send_kwargs)
  File "/home/ubuntu/anaconda3/envs/lrx/lib/python3.9/site-packages/requests/sessions.py", line 703, in send
    r = adapter.send(request, **kwargs)
  File "/home/ubuntu/anaconda3/envs/lrx/lib/python3.9/site-packages/requests/adapters.py", line 507, in send
    raise ConnectTimeout(e, request=request)
requests.exceptions.ConnectTimeout: HTTPSConnectionPool(host='api.wandb.ai', port=443): Max retries exceeded with url: /graphql (Caused by ConnectTimeoutError(<urllib3.connection.HTTPSConnection object at 0x7f1ab86e4a00>, 'Connection to api.wandb.ai timed out. (connect timeout=10)'))
2024-04-13 02:06:59,713 ERROR   MainThread:9709 [wandb_init.py:init():756] encountered error: Run initialization has timed out after 60.0 sec. 
Please refer to the documentation for additional information: https://docs.wandb.ai/guides/track/tracking-faq#initstarterror-error-communicating-with-wandb-process-
2024-04-13 02:07:01,723 ERROR   MainThread:9709 [wandb_init.py:init():1165] Run initialization has timed out after 60.0 sec. 
Please refer to the documentation for additional information: https://docs.wandb.ai/guides/track/tracking-faq#initstarterror-error-communicating-with-wandb-process-
Traceback (most recent call last):
  File "/home/ubuntu/anaconda3/envs/lrx/lib/python3.9/site-packages/wandb/sdk/wandb_init.py", line 1147, in init
    run = wi.init()
  File "/home/ubuntu/anaconda3/envs/lrx/lib/python3.9/site-packages/wandb/sdk/wandb_init.py", line 762, in init
    raise error
wandb.errors.CommError: Run initialization has timed out after 60.0 sec. 
Please refer to the documentation for additional information: https://docs.wandb.ai/guides/track/tracking-faq#initstarterror-error-communicating-with-wandb-process-
2024-04-13 02:07:07,484 WARNING MsgRouterThr:9709 [router.py:message_loop():77] message_loop has been closed
